Workbook

Sheet MESA
A1: Preparação da sessão — o que a mesa pede hoje
A2: Preencha só as três colunas amareladas. Todo o resto se calcula sozinho.
A4: 1 · A MESA
A5: ALUNO | B5: EVOLVE | C5: UN. | D5: TÍTULO DA UNIDADE | E5: AÇÃO 1 | F5: AÇÃO 2 | G5: DOMÍNIO | H5: CONFERE?
A6: Ana | B6: 3 | C6: 9 | D6: =IFERROR(INDEX(ETIQUETAS!$E$2:$E$73,MATCH($B6&"|"&$C6,ETIQUETAS!$A$2:$A$73,0))&"","") | E6: =IFERROR(INDEX(ETIQUETAS!$G$2:$G$73,MATCH($B6&"|"&$C6,ETIQUETAS!$A$2:$A$73,0))&"","") | F6: =IFERROR(INDEX(ETIQUETAS!$H$2:$H$73,MATCH($B6&"|"&$C6,ETIQUETAS!$A$2:$A$73,0))&"","") | G6: =IFERROR(INDEX(ETIQUETAS!$I$2:$I$73,MATCH($B6&"|"&$C6,ETIQUETAS!$A$2:$A$73,0))&"","") | H6: =IF($D6="","unidade não existe","ok")
A7: Mira | B7: 1 | C7: 6 | D7: =IFERROR(INDEX(ETIQUETAS!$E$2:$E$73,MATCH($B7&"|"&$C7,ETIQUETAS!$A$2:$A$73,0))&"","") | E7: =IFERROR(INDEX(ETIQUETAS!$G$2:$G$73,MATCH($B7&"|"&$C7,ETIQUETAS!$A$2:$A$73,0))&"","") | F7: =IFERROR(INDEX(ETIQUETAS!$H$2:$H$73,MATCH($B7&"|"&$C7,ETIQUETAS!$A$2:$A$73,0))&"","") | G7: =IFERROR(INDEX(ETIQUETAS!$I$2:$I$73,MATCH($B7&"|"&$C7,ETIQUETAS!$A$2:$A$73,0))&"","") | H7: =IF($D7="","unidade não existe","ok")
A8: Diego | B8: 4 | C8: 5 | D8: =IFERROR(INDEX(ETIQUETAS!$E$2:$E$73,MATCH($B8&"|"&$C8,ETIQUETAS!$A$2:$A$73,0))&"","") | E8: =IFERROR(INDEX(ETIQUETAS!$G$2:$G$73,MATCH($B8&"|"&$C8,ETIQUETAS!$A$2:$A$73,0))&"","") | F8: =IFERROR(INDEX(ETIQUETAS!$H$2:$H$73,MATCH($B8&"|"&$C8,ETIQUETAS!$A$2:$A$73,0))&"","") | G8: =IFERROR(INDEX(ETIQUETAS!$I$2:$I$73,MATCH($B8&"|"&$C8,ETIQUETAS!$A$2:$A$73,0))&"","") | H8: =IF($D8="","unidade não existe","ok")
A9: Lu | B9: 2 | C9: 10 | D9: =IFERROR(INDEX(ETIQUETAS!$E$2:$E$73,MATCH($B9&"|"&$C9,ETIQUETAS!$A$2:$A$73,0))&"","") | E9: =IFERROR(INDEX(ETIQUETAS!$G$2:$G$73,MATCH($B9&"|"&$C9,ETIQUETAS!$A$2:$A$73,0))&"","") | F9: =IFERROR(INDEX(ETIQUETAS!$H$2:$H$73,MATCH($B9&"|"&$C9,ETIQUETAS!$A$2:$A$73,0))&"","") | G9: =IFERROR(INDEX(ETIQUETAS!$I$2:$I$73,MATCH($B9&"|"&$C9,ETIQUETAS!$A$2:$A$73,0))&"","") | H9: =IF($D9="","unidade não existe","ok")
A11: 2 · QUEM CADA AÇÃO ALCANÇA | D11: Linha cheia = cena com essa ação já mira esses alunos sem adaptação nenhuma.
A12: AÇÃO | B12: =$A$6 | C12: =$A$7 | D12: =$A$8 | E12: =$A$9 | F12: ALCANÇA
A13: Identify | B13: =IF(COUNTIF($E6:$F6,$A13)>0,$A$6,"") | C13: =IF(COUNTIF($E7:$F7,$A13)>0,$A$7,"") | D13: =IF(COUNTIF($E8:$F8,$A13)>0,$A$8,"") | E13: =IF(COUNTIF($E9:$F9,$A13)>0,$A$9,"") | F13: =COUNTIF($E$6:$F$9,$A13)
A14: Describe | B14: =IF(COUNTIF($E6:$F6,$A14)>0,$A$6,"") | C14: =IF(COUNTIF($E7:$F7,$A14)>0,$A$7,"") | D14: =IF(COUNTIF($E8:$F8,$A14)>0,$A$8,"") | E14: =IF(COUNTIF($E9:$F9,$A14)>0,$A$9,"") | F14: =COUNTIF($E$6:$F$9,$A14)
A15: Quantify | B15: =IF(COUNTIF($E6:$F6,$A15)>0,$A$6,"") | C15: =IF(COUNTIF($E7:$F7,$A15)>0,$A$7,"") | D15: =IF(COUNTIF($E8:$F8,$A15)>0,$A$8,"") | E15: =IF(COUNTIF($E9:$F9,$A15)>0,$A$9,"") | F15: =COUNTIF($E$6:$F$9,$A15)
A16: Ability & Progress | B16: =IF(COUNTIF($E6:$F6,$A16)>0,$A$6,"") | C16: =IF(COUNTIF($E7:$F7,$A16)>0,$A$7,"") | D16: =IF(COUNTIF($E8:$F8,$A16)>0,$A$8,"") | E16: =IF(COUNTIF($E9:$F9,$A16)>0,$A$9,"") | F16: =COUNTIF($E$6:$F$9,$A16)
A17: Narrate | B17: =IF(COUNTIF($E6:$F6,$A17)>0,$A$6,"") | C17: =IF(COUNTIF($E7:$F7,$A17)>0,$A$7,"") | D17: =IF(COUNTIF($E8:$F8,$A17)>0,$A$8,"") | E17: =IF(COUNTIF($E9:$F9,$A17)>0,$A$9,"") | F17: =COUNTIF($E$6:$F$9,$A17)
A18: Report | B18: =IF(COUNTIF($E6:$F6,$A18)>0,$A$6,"") | C18: =IF(COUNTIF($E7:$F7,$A18)>0,$A$7,"") | D18: =IF(COUNTIF($E8:$F8,$A18)>0,$A$8,"") | E18: =IF(COUNTIF($E9:$F9,$A18)>0,$A$9,"") | F18: =COUNTIF($E$6:$F$9,$A18)
A19: Plan | B19: =IF(COUNTIF($E6:$F6,$A19)>0,$A$6,"") | C19: =IF(COUNTIF($E7:$F7,$A19)>0,$A$7,"") | D19: =IF(COUNTIF($E8:$F8,$A19)>0,$A$8,"") | E19: =IF(COUNTIF($E9:$F9,$A19)>0,$A$9,"") | F19: =COUNTIF($E$6:$F$9,$A19)
A20: Regulate | B20: =IF(COUNTIF($E6:$F6,$A20)>0,$A$6,"") | C20: =IF(COUNTIF($E7:$F7,$A20)>0,$A$7,"") | D20: =IF(COUNTIF($E8:$F8,$A20)>0,$A$8,"") | E20: =IF(COUNTIF($E9:$F9,$A20)>0,$A$9,"") | F20: =COUNTIF($E$6:$F$9,$A20)
A21: Speculate | B21: =IF(COUNTIF($E6:$F6,$A21)>0,$A$6,"") | C21: =IF(COUNTIF($E7:$F7,$A21)>0,$A$7,"") | D21: =IF(COUNTIF($E8:$F8,$A21)>0,$A$8,"") | E21: =IF(COUNTIF($E9:$F9,$A21)>0,$A$9,"") | F21: =COUNTIF($E$6:$F$9,$A21)
A22: Suppose | B22: =IF(COUNTIF($E6:$F6,$A22)>0,$A$6,"") | C22: =IF(COUNTIF($E7:$F7,$A22)>0,$A$7,"") | D22: =IF(COUNTIF($E8:$F8,$A22)>0,$A$8,"") | E22: =IF(COUNTIF($E9:$F9,$A22)>0,$A$9,"") | F22: =COUNTIF($E$6:$F$9,$A22)
A23: Argue | B23: =IF(COUNTIF($E6:$F6,$A23)>0,$A$6,"") | C23: =IF(COUNTIF($E7:$F7,$A23)>0,$A$7,"") | D23: =IF(COUNTIF($E8:$F8,$A23)>0,$A$8,"") | E23: =IF(COUNTIF($E9:$F9,$A23)>0,$A$9,"") | F23: =COUNTIF($E$6:$F$9,$A23)
A24: React | B24: =IF(COUNTIF($E6:$F6,$A24)>0,$A$6,"") | C24: =IF(COUNTIF($E7:$F7,$A24)>0,$A$7,"") | D24: =IF(COUNTIF($E8:$F8,$A24)>0,$A$8,"") | E24: =IF(COUNTIF($E9:$F9,$A24)>0,$A$9,"") | F24: =COUNTIF($E$6:$F$9,$A24)
A25: Register & Nuance | B25: =IF(COUNTIF($E6:$F6,$A25)>0,$A$6,"") | C25: =IF(COUNTIF($E7:$F7,$A25)>0,$A$7,"") | D25: =IF(COUNTIF($E8:$F8,$A25)>0,$A$8,"") | E25: =IF(COUNTIF($E9:$F9,$A25)>0,$A$9,"") | F25: =COUNTIF($E$6:$F$9,$A25)
A27: MELHOR HOJE | B27: =IF(MAX($F$13:$F$25)=0,"—",INDEX($A$13:$A$25,MATCH(MAX($F$13:$F$25),$F$13:$F$25,0))&" ("&MAX($F$13:$F$25)&" de 4)")
A29: 3 · A CENA QUE VOCÊ PLANEJOU | D29: Escolha até três ações que a cena puxa. A tabela diz quem fica de fora e o que fazer.
A30: Ação 1 da cena | B30: Regulate
A31: Ação 2 da cena | B31: Identify
A32: Ação 3 da cena
A34: ALUNO | B34: SITUAÇÃO | C34: SE FICOU DE FORA, PEÇA ISTO NA CENA
A35: =$A$6 | B35: =IF(COUNTIF($E6:$F6,$B$30)+COUNTIF($E6:$F6,$B$31)+COUNTIF($E6:$F6,$B$32)>0,"coberto","FALTA") | C35: =IF(COUNTIF($E6:$F6,$B$30)+COUNTIF($E6:$F6,$B$31)+COUNTIF($E6:$F6,$B$32)>0,"","Inclua uma fala de NPC que peça "&$E6&IF($F6="",""," ou "&$F6)&" — "&$D6)
A36: =$A$7 | B36: =IF(COUNTIF($E7:$F7,$B$30)+COUNTIF($E7:$F7,$B$31)+COUNTIF($E7:$F7,$B$32)>0,"coberto","FALTA") | C36: =IF(COUNTIF($E7:$F7,$B$30)+COUNTIF($E7:$F7,$B$31)+COUNTIF($E7:$F7,$B$32)>0,"","Inclua uma fala de NPC que peça "&$E7&IF($F7="",""," ou "&$F7)&" — "&$D7)
A37: =$A$8 | B37: =IF(COUNTIF($E8:$F8,$B$30)+COUNTIF($E8:$F8,$B$31)+COUNTIF($E8:$F8,$B$32)>0,"coberto","FALTA") | C37: =IF(COUNTIF($E8:$F8,$B$30)+COUNTIF($E8:$F8,$B$31)+COUNTIF($E8:$F8,$B$32)>0,"","Inclua uma fala de NPC que peça "&$E8&IF($F8="",""," ou "&$F8)&" — "&$D8)
A38: =$A$9 | B38: =IF(COUNTIF($E9:$F9,$B$30)+COUNTIF($E9:$F9,$B$31)+COUNTIF($E9:$F9,$B$32)>0,"coberto","FALTA") | C38: =IF(COUNTIF($E9:$F9,$B$30)+COUNTIF($E9:$F9,$B$31)+COUNTIF($E9:$F9,$B$32)>0,"","Inclua uma fala de NPC que peça "&$E9&IF($F9="",""," ou "&$F9)&" — "&$D9)
A40: A coluna da direita é o ajuste de trinta segundos: você não muda a cena, só acrescenta uma fala de NPC que peça daquele aluno o que ele está estudando. Quem faz cada ação naturalmente está na aba ACOES do catálogo — Halden, Piro, Sable, Quill ou The Tenant.

Sheet ETIQUETAS
A1: CHAVE | B1: NÍVEL | C1: EVOLVE | D1: UN. | E1: TÍTULO | F1: GRAMÁTICA | G1: AÇÃO 1 | H1: AÇÃO 2 | I1: DOMÍNIO
A2: 1|1 | B2: A1 | C2: 1 | D2: 1 | E2: I am… | F2: I am, you are; What's…?; It's… | G2: Identify | I2: People & Relationships
A3: 1|2 | B3: A1 | C3: 1 | D3: 2 | E3: Great people | F3: is/are (afirm. e pergunta); is not/are not | G3: Identify | H3: Describe | I3: People & Relationships
A4: 1|3 | B4: A1 | C4: 1 | D4: 3 | E4: Come in | F4: Possessive adjectives; possessive 's e s'; It is | G4: Describe | H4: Identify | I4: Places & Environment
A5: 1|4 | B5: A1 | C5: 1 | D5: 4 | E5: I love it! | F5: Simple present (I/you/we); pergunta sim/não | G5: Describe | H5: Argue | I5: Objects & Technology
A6: 1|5 | B6: A1 | C6: 1 | D6: 5 | E6: Mondays and fundays | F6: Simple present (he/she/they); questions | G6: Describe | I6: People & Relationships
A7: 1|6 | B7: A1 | C7: 1 | D7: 6 | E7: Zoom in, zoom out | F7: There's/There are; a lot of, some, no; count/non-count | G7: Quantify | H7: Describe | I7: Places & Environment
A8: 1|7 | B8: A1 | C8: 1 | D8: 7 | E8: Now is good | F8: Present continuous (afirm. e pergunta) | G8: Describe | I8: Places & Environment
A9: 1|8 | B9: A1 | C9: 1 | D9: 8 | E9: You're good! | F9: can/can't (habilidade e possibilidade); well | G9: Ability & Progress | H9: Describe | I9: Work & Learning
A10: 1|9 | B10: A1 | C10: 1 | D10: 9 | E10: Places to go | F10: this/these; like to, want to, need to, have to | G10: Plan | H10: Regulate | I10: Journeys & Movement
A11: 1|10 | B11: A1 | C11: 1 | D11: 10 | E11: Get ready | F11: be going to (afirm. e pergunta) | G11: Plan | I11: Society & Culture
A12: 1|11 | B12: A1 | C12: 1 | D12: 11 | E12: Colorful memories | F12: was/were (afirm. e pergunta) | G12: Narrate | H12: Describe | I12: Places & Environment
A13: 1|12 | B13: A1 | C13: 1 | D13: 12 | E13: Stop, eat, go | F13: Simple past (afirm. e pergunta); any | G13: Narrate | H13: Quantify | I13: Body, Food & Health
A14: 2|1 | B14: A2 | C14: 2 | D14: 1 | E14: Connections | F14: be; possessive adjectives e pronouns; possessive 's | G14: Identify | I14: People & Relationships
A15: 2|2 | B15: A2 | C15: 2 | D15: 2 | E15: Work and Study | F15: Simple present (hábitos); adverbs of frequency; demonstratives | G15: Describe | I15: Work & Learning
A16: 2|3 | B16: A2 | C16: 2 | D16: 3 | E16: Let's Move | F16: Present continuous; contraste simple present x continuous | G16: Describe | I16: Body, Food & Health
A17: 2|4 | B17: A2 | C17: 2 | D17: 4 | E17: Good Times | F17: Present continuous (planos futuros); object pronouns | G17: Plan | H17: Describe | I17: Society & Culture
A18: 2|5 | B18: A2 | C18: 2 | D18: 5 | E18: Firsts and Lasts | F18: Simple past (afirm., neg. e pergunta) | G18: Narrate | H18: React | I18: People & Relationships
A19: 2|6 | B19: A2 | C19: 2 | D19: 6 | E19: Buy Now, Pay Later | F19: be going to; determiners (no/none, some, many, most, all) | G19: Plan | H19: Quantify | I19: Trade & Value
A20: 2|7 | B20: A2 | C20: 2 | D20: 7 | E20: Eat, Drink, Be Happy | F20: Quantifiers; verb patterns | G20: Quantify | H20: Describe | I20: Body, Food & Health
A21: 2|8 | B21: A2 | C21: 2 | D21: 8 | E21: Trips | F21: if/when; giving reasons with to/for | G21: Plan | H21: Argue | I21: Journeys & Movement
A22: 2|9 | B22: A2 | C22: 2 | D22: 9 | E22: Looking Good | F22: Comparative and superlative adjectives | G22: Describe | I22: People & Relationships
A23: 2|10 | B23: A2 | C23: 2 | D23: 10 | E23: Risky Business | F23: have to; predictions com will/may/might | G23: Speculate | H23: Regulate | I23: Work & Learning
A24: 2|11 | B24: A2 | C24: 2 | D24: 11 | E24: Me, Online | F24: Present perfect (experiências); present perfect x simple past | G24: Narrate | H24: Ability & Progress | I24: Society & Culture
A25: 2|12 | B25: A2 | C25: 2 | D25: 12 | E25: Outdoors | F25: be like; relative pronouns (who/which/that) | G25: Describe | I25: Places & Environment
A26: 3|1 | B26: B1 | C26: 3 | D26: 1 | E26: Who we are | F26: Information questions; indirect questions | G26: Identify | H26: Register & Nuance | I26: People & Relationships
A27: 3|2 | B27: B1 | C27: 3 | D27: 2 | E27: So much stuff | F27: Present perfect (ever/never/for/since; already/yet) | G27: Narrate | H27: Describe | I27: Objects & Technology
A28: 3|3 | B28: B1 | C28: 3 | D28: 3 | E28: Smart moves | F28: Articles; modals for advice | G28: Regulate | H28: Describe | I28: Places & Environment
A29: 3|4 | B29: B1 | C29: 3 | D29: 4 | E29: Think first | F29: be going to/will; will (decisão súbita); present continuous (futuro) | G29: Plan | H29: Speculate | I29: People & Relationships
A30: 3|5 | B30: B1 | C30: 3 | D30: 5 | E30: And then… | F30: Simple past; past continuous x simple past | G30: Narrate | I30: People & Relationships
A31: 3|6 | B31: B1 | C31: 3 | D31: 6 | E31: Impact | F31: Quantifiers; real conditionals (presente e futuro) | G31: Argue | H31: Quantify | I31: Places & Environment
A32: 3|7 | B32: B1 | C32: 3 | D32: 7 | E32: Entertain us | F32: used to; comparisons (not) as…as | G32: Narrate | H32: Describe | I32: Society & Culture
A33: 3|8 | B33: B1 | C33: 3 | D33: 8 | E33: Getting there | F33: Present perfect continuous; contraste com present perfect | G33: Ability & Progress | H33: Narrate | I33: Work & Learning
A34: 3|9 | B34: B1 | C34: 3 | D34: 9 | E34: Make it work | F34: Modais de necessidade; modais de proibição e permissão | G34: Regulate | I34: Work & Learning
A35: 3|10 | B35: B1 | C35: 3 | D35: 10 | E35: Why we buy | F35: Simple present passive; simple past passive | G35: Describe | H35: Narrate | I35: Trade & Value
A36: 3|11 | B36: B1 | C36: 3 | D36: 11 | E36: Pushing yourself | F36: Phrasal verbs; unreal conditionals (presente e futuro) | G36: Suppose | H36: Ability & Progress | I36: People & Relationships
A37: 3|12 | B37: B1 | C37: 3 | D37: 12 | E37: Life's little lessons | F37: Indefinite pronouns; reported speech | G37: Report | H37: Narrate | I37: People & Relationships
A38: 4|1 | B38: B1+ | C38: 4 | D38: 1 | E38: And we're off! | F38: Tense review (simple e continuous); dynamic and stative verbs | G38: Describe | H38: Ability & Progress | I38: People & Relationships
A39: 4|2 | B39: B1+ | C39: 4 | D39: 2 | E39: The future of food | F39: Real conditionals; clauses com after/until/when | G39: Plan | H39: Speculate | I39: Body, Food & Health
A40: 4|3 | B40: B1+ | C40: 4 | D40: 3 | E40: What's it worth? | F40: too/enough; modifying comparisons | G40: Quantify | H40: Argue | I40: Trade & Value
...

Sheet INSTALAR
B2: Como plugar isto no seu Painel da Turma
B3: Cinco minutos, uma vez só. Depois disso nunca mais.
B5: SE VOCÊ QUER O MAIS SIMPLES
B6: Use esta planilha como está. Toda semana você abre a aba MESA, atualiza as colunas EVOLVE e UN. de cada aluno, e lê os blocos 2 e 3. Não precisa mexer no Painel.
B8: SE VOCÊ QUER DENTRO DO PAINEL (recomendado a médio prazo)
B9: 1. Abra o Painel-Turma-RPL no Google Sheets.
B10: 2. Nesta planilha, clique com o botão direito na aba ETIQUETAS e escolha Copiar para → Planilha existente → Painel-Turma-RPL. Faça o mesmo com a aba MESA.
B11: 3. Na aba MESA copiada, troque as colunas A, B e C para apontar para o PAINEL. Se o primeiro aluno estiver na linha 7 do PAINEL, com nível em B7 e unidade em C7, então na MESA escreva:
B12: A6: =PAINEL!A7 B6: =PAINEL!B7 C6: =PAINEL!C7
B13: 4. Arraste as três células para baixo, uma linha por aluno. Pronto — a partir daí a MESA se atualiza sozinha toda vez que você marcar a etapa de alguém.
B15: SE VOCÊ PREFERIR AS COLUNAS DIRETO NO PAINEL
B16: Em vez de usar a aba MESA, cole a fórmula abaixo numa coluna nova do PAINEL, ao lado de cada aluno. Ela devolve a Ação 1. Troque $B7 pelo nível do Evolve e $C7 pela unidade:
B17: =IFERROR(INDEX(ETIQUETAS!$G$2:$G$73;MATCH($B7&"|"&$C7;ETIQUETAS!$A$2:$A$73;0));"")
B18: Para a Ação 2, troque G por H. Para o domínio, troque por I. Para o título da unidade, E.
B19: Atenção ao separador: o Google Sheets em português usa ponto e vírgula, como está acima. Se a sua planilha usa vírgula, troque todos os ; por ,
B21: O QUE NÃO FAZER
B22: Não apague nem reordene as colunas da aba ETIQUETAS. As fórmulas apontam para as letras das colunas, então mover uma coluna quebra tudo em silêncio.
B23: Não use ARRAYFORMULA para tentar preencher a coluna de uma vez. Funciona no Google Sheets e quebra no Excel e no LibreOffice — e o material precisa rodar na máquina de qualquer professor parceiro.
B25: QUANDO O CATÁLOGO MUDAR
B26: Se as etiquetas de alguma unidade forem revistas, o que muda é só a aba ETIQUETAS. Nenhuma fórmula precisa ser tocada — troque os valores das colunas G, H e I e o resto acompanha.
